Traceback (most recent call last):
  File "./manage.py", line 10, in <module>
    execute_from_command_line(sys.argv)
  File "/Users/bongster/.virtualenvs/urqa/lib/python2.7/site-packages/django/core/management/__init__.py", line 385, in execute_from_command_line
    utility.execute()
  File "/Users/bongster/.virtualenvs/urqa/lib/python2.7/site-packages/django/core/management/__init__.py", line 345, in execute
    settings.INSTALLED_APPS
  File "/Users/bongster/.virtualenvs/urqa/lib/python2.7/site-packages/django/conf/__init__.py", line 46, in __getattr__
    self._setup(name)
  File "/Users/bongster/.virtualenvs/urqa/lib/python2.7/site-packages/django/conf/__init__.py", line 42, in _setup
    self._wrapped = Settings(settings_module)
  File "/Users/bongster/.virtualenvs/urqa/lib/python2.7/site-packages/django/conf/__init__.py", line 94, in __init__
    mod = importlib.import_module(self.SETTINGS_MODULE)
  File "/System/Library/Frameworks/Python.framework/Versions/2.7/lib/python2.7/importlib/__init__.py", line 37, in import_module
    __import__(name)
  File "/Users/bongster/Documents/workSpace/pythonWorkSpace/URQA-Server/soma3/soma3/settings.py", line 33, in <module>
    'USER': os.environ['URQA_USER'],
  File "/Users/bongster/.virtualenvs/urqa/lib/python2.7/UserDict.py", line 23, in __getitem__
    raise KeyError(key)
KeyError: 'URQA_USER'
